Workbook
Name Slicer_Month_Sort: #N/A
Name Slicer_regional_office: #N/A

Sheet Dashboard
N24: Sales Agent | O24: =PivotTables!C52 -> Total_Sales | P24: =PivotTables!D52 -> Won_ Deals | Q24: =PivotTables!E52 -> Win_Rate% | R24: =PivotTables!F52 -> Avg_Sales_Cycle | S24: =PivotTables!G52 -> Avg_Deal_Value
N25: =PivotTables!B53 -> Darcel Schlecht | O25: =PivotTables!C53 -> 1153214 | P25: =PivotTables!D53 -> 349 | Q25: =PivotTables!E53 -> 0.46720214 | R25: =PivotTables!F53 -> 45.842676 | S25: =PivotTables!G53 -> 3304.3381
N26: =PivotTables!B54 -> Vicki Laflamme | O26: =PivotTables!C54 -> 478396 | P26: =PivotTables!D54 -> 221 | Q26: =PivotTables!E54 -> 0.49002217 | R26: =PivotTables!F54 -> 46.556196 | S26: =PivotTables!G54 -> 2164.6878
N27: =PivotTables!B55 -> Kary Hendrixson | O27: =PivotTables!C55 -> 454298 | P27: =PivotTables!D55 -> 209 | Q27: =PivotTables!E55 -> 0.47716895 | R27: =PivotTables!F55 -> 49.850746 | S27: =PivotTables!G55 -> 2173.6746
N28: =PivotTables!B56 -> Cassey Cress | O28: =PivotTables!C56 -> 450489 | P28: =PivotTables!D56 -> 163 | Q28: =PivotTables!E56 -> 0.47109827 | R28: =PivotTables!F56 -> 45.961686 | S28: =PivotTables!G56 -> 2763.7362
N29: =PivotTables!B57 -> Donn Cantrell | O29: =PivotTables!C57 -> 445860 | P29: =PivotTables!D57 -> 158 | Q29: =PivotTables!E57 -> 0.57454545 | R29: =PivotTables!F57 -> 48.930909 | S29: =PivotTables!G57 -> 2821.8987
N30: =PivotTables!B58 -> Reed Clapper | O30: =PivotTables!C58 -> 438336 | P30: =PivotTables!D58 -> 155 | Q30: =PivotTables!E58 -> 0.65400844 | R30: =PivotTables!F58 -> 44.565401 | S30: =PivotTables!G58 -> 2827.9742
N31: =PivotTables!B59 -> Zane Levy | O31: =PivotTables!C59 -> 430068 | P31: =PivotTables!D59 -> 161 | Q31: =PivotTables!E59 -> 0.46131805 | R31: =PivotTables!F59 -> 44.413793 | S31: =PivotTables!G59 -> 2671.2298
N32: =PivotTables!B60 -> Corliss Cosme | O32: =PivotTables!C60 -> 421036 | P32: =PivotTables!D60 -> 150 | Q32: =PivotTables!E60 -> 0.48387097 | R32: =PivotTables!F60 -> 47.218341 | S32: =PivotTables!G60 -> 2806.9067
N33: =PivotTables!B61 -> James Ascencio | O33: =PivotTables!C61 -> 413533 | P33: =PivotTables!D61 -> 135 | Q33: =PivotTables!E61 -> 0.50561798 | R33: =PivotTables!F61 -> 50.485437 | S33: =PivotTables!G61 -> 3063.2074
N34: =PivotTables!B62 -> Daniell Hammack | O34: =PivotTables!C62 -> 364229 | P34: =PivotTables!D62 -> 114 | Q34: =PivotTables!E62 -> 0.44015444 | R34: =PivotTables!F62 -> 44.860963 | S34: =PivotTables!G62 -> 3194.9912

Sheet PivotTables
B5: Total_Sales
B6: 10005534
B10: Row Labels | C10: Total_Sales
B11: Mar | C11: 1134672 | F11: Row Labels | G11: Average_Sales_Cycle
B12: Apr | C12: 721932 | F12: Lost | G12: 41.479175
B13: May | C13: 1025713 | F13: Won | G13: 51.781973
B14: Jun | C14: 1338466 | F14: Grand Total | G14: 47.985397
B15: Jul | C15: 696932
B16: Aug | C16: 1050059
B17: Sep | C17: 1235264
B18: Oct | C18: 731980
B19: Nov | C19: 938943
B20: Dec | C20: 1131573
B21: Grand Total | C21: 10005534
L26: Row Labels | M26: Total_Sales
L27: Kan-code | M27: 341455
L28: Konex | M28: 269245
L29: Condax | M29: 206410
L30: Cheers | M30: 198020
L31: Hottechi | M31: 194957
L32: Goodsilron | M32: 182522
L33: Treequote | M33: 176751
B34: Row Labels | C34: Total_Sales | L34: Warephase | M34: 170046
B35: MG Special | C35: 43768 | L35: Xx-holding | M35: 169357
B36: GTK 500 | C36: 400612 | L36: Isdom | M36: 164683
B37: GTX Basic | C37: 499263 | L37: Grand Total | M37: 2073446
B38: GTX Plus Basic | C38: 705275
B39: MG Advanced | C39: 2216387
B40: GTX Plus Pro | C40: 2629651
B41: GTX Pro | C41: 3510578
B42: Grand Total | C42: 10005534
F44: Row Labels | G44: Count of opportunity_id
F45: Engaging | G45: 0.18056818
F46: Lost | G46: 0.28102273
F47: Prospecting | G47: 0.056818182
F48: Won | G48: 0.48159091
F49: Grand Total | G49: 1
B52: Row Labels | C52: Total_Sales | D52: Won_ Deals | E52: Win_Rate% | F52: Avg_Sales_Cycle | G52: Avg_Deal_Value
B53: Darcel Schlecht | C53: 1153214 | D53: 349 | E53: 0.46720214 | F53: 45.842676 | G53: 3304.3381
B54: Vicki Laflamme | C54: 478396 | D54: 221 | E54: 0.49002217 | F54: 46.556196 | G54: 2164.6878
...
